<?xml version="1.0"?>
<robot name="naverr" xmlns:xacro="http://www.ros.org/wiki/xacro">

	<xacro:property name="mass" value="1" />
	<xacro:property name="wh_m" value="0.1" />
	<xacro:property name="h" value=".1" />
	<xacro:property name="l" value=".4" />
	<xacro:property name="w" value=".2" />

	<xacro:property name="wh_h" value="0.05" />
	<xacro:property name="wh_r" value=".1" />

	<xacro:include filename="$(find naverr_description)/urdf/naverr_four.gazebo" />

	<link name="chassis">
		<collision>
			<origin xyz="0 0 0" rpy="0 0 0"/>
			<geometry>
				<box size="${w} ${l} ${h}"/>
			</geometry>
		</collision>

		<visual>
			<origin xyz="0 0 0" rpy="0 0 0"/>
			<geometry>
				<box size="${w} ${l} ${h}"/>
			</geometry>
			<color rgba="0.2 0.2 0.2 1.0"/>
		</visual>

		<inertial>
			<origin xyz="0 0 0" rpy="0 0 0"/>
			<mass value="${mass}"/>
			<inertia
	  ixx="${mass / 12.0 * (l*l + h*h)}" ixy="0.0" ixz="0.0"
	  iyy="${mass / 12.0 * (h*h + w*w)}" iyz="0.0"
	  izz="${mass / 12.0 * (l*l + w*w)}"/>
		</inertial>


	</link>

	<joint name="steer_r1_hinge" type="fixed">
		<parent link="chassis"/>
		<child link="steer_r1"/>
		<origin xyz="${w/2} ${l/2} 0" rpy="0 0 0"/>
		<axis xyz="0 0 1"/>
		<limit lower="-0.52" upper="0.52" effort="1000" velocity="1000"/>
	</joint>
	
	<joint name="steer_l1_hinge" type="fixed">
		<parent link="chassis"/>
		<child link="steer_l1"/>
		<origin xyz="${-w/2} ${l/2} 0" rpy="0 0 0"/>
		<axis xyz="0 0 1"/>
		<limit lower="-0.52" upper="0.52" effort="1000" velocity="1000"/>
	</joint>

	<joint name="wheel_r1_hinge" type="continuous">
		<parent link="steer_r1"/>
		<child link="wheel_r1"/>
		<origin xyz="${0.05} 0 0" rpy="0 0 0"/>
		<axis xyz="1 0 0"/>
	</joint>


	<joint name="wheel_l1_hinge" type="continuous">
		<parent link="steer_l1"/>
		<child link="wheel_l1"/>
		<origin xyz="${-0.05} 0 0" rpy="0 0 0"/>
		<axis xyz="1 0 0"/>
	</joint>


	<joint name="wheel_r2_hinge" type="continuous">
		<parent link="chassis"/>
		<child link="wheel_r2"/>
		<origin xyz="${w/2} ${-l/2} 0" rpy="0 0 0"/>
		<axis xyz="1 0 0"/>
	</joint>


	<joint name="wheel_l2_hinge" type="continuous">
		<parent link="chassis"/>
		<child link="wheel_l2"/>
		<origin xyz="${-w/2} ${-l/2} 0" rpy="0 0 0"/>
		<axis xyz="1 0 0"/>
	</joint>

	<link name="steer_r1">
		<collision>
			<origin xyz="0 0 0" rpy="0 0 0"/>
			<geometry>
				<box size="0.01 0.01 0.01"/>
			</geometry>
		</collision>

		<visual>
			<origin xyz="0 0 0" rpy="0 0 0"/>
			<geometry>
				<box size="0.01 0.01 0.01"/>
			</geometry>
		</visual>

		<inertial>
			<origin xyz="0 0 0" rpy="0 0 0"/>
			<mass value="0.01"/>
			<inertia
	  ixx="${wh_m / 12.0 * (0.0001 + 0.0001)}" ixy="0.0" ixz="0.0"
	  iyy="${wh_m / 12.0 * (0.0001 + 0.0001)}" iyz="0.0"
	  izz="${wh_m / 12.0 * (0.0001 + 0.0001)}"/>
		</inertial>

	</link>
	
	<link name="steer_l1">
		<collision>
			<origin xyz="0 0 0" rpy="0 0 0"/>
			<geometry>
				<box size="0.01 0.01 0.01"/>
			</geometry>
		</collision>

		<visual>
			<origin xyz="0 0 0" rpy="0 0 0"/>
			<geometry>
				<box size="0.01 0.01 0.01"/>
			</geometry>
		</visual>

		<inertial>
			<origin xyz="0 0 0" rpy="0 0 0"/>
			<mass value="0.01"/>
			<inertia
	  ixx="${wh_m / 12.0 * (0.0001 + 0.0001)}" ixy="0.0" ixz="0.0"
	  iyy="${wh_m / 12.0 * (0.0001 + 0.0001)}" iyz="0.0"
	  izz="${wh_m / 12.0 * (0.0001 + 0.0001)}"/>
		</inertial>

	</link>

	<link name="wheel_r1">
		<collision>
			<origin xyz="${wh_h/2 + 0.01} 0 0" rpy="0 1.57075 0"/>
			<geometry>
				<cylinder length="${wh_h}" radius="${wh_r}"/>
			</geometry>
		</collision>

		<visual>
			<origin xyz="${wh_h/2 + 0.01} 0 0" rpy="0 1.57075 0"/>
			<geometry>
				<cylinder length="${wh_h}" radius="${wh_r}"/>
			</geometry>
		</visual>

		<inertial>
			<origin xyz="${wh_h/2 + 0.01} 0 0" rpy="0 1.57075 0"/>
			<mass value="${wh_m}"/>
			<inertia
	  ixx="${wh_m / 12.0 * (3 * wh_r * wh_r + wh_h*wh_h)}" ixy="0.0" ixz="0.0"
	  iyy="${wh_m / 12.0 * (3 * wh_r * wh_r + wh_h*wh_h)}" iyz="0.0"
	  izz="${wh_m / 2.0 * (wh_r * wh_r)}"/>
		</inertial>

	</link>

	<link name="wheel_l1">
		<collision>
			<origin xyz="${-wh_h/2 - 0.01} 0 0" rpy="0 1.57075 0"/>
			<geometry>
				<cylinder length="${wh_h}" radius="${wh_r}"/>
			</geometry>
		</collision>

		<visual>
			<origin xyz="${-wh_h/2 - 0.01} 0 0" rpy="0 1.57075 0"/>
			<geometry>
				<cylinder length="${wh_h}" radius="${wh_r}"/>
			</geometry>
		</visual>

		<inertial>
			<origin xyz="${-wh_h/2 - 0.01} 0 0" rpy="0 1.57075 0"/>
			<mass value="${wh_m}"/>
			<inertia
	  ixx="${wh_m / 12.0 * (3 * wh_r * wh_r + wh_h*wh_h)}" ixy="0.0" ixz="0.0"
	  iyy="${wh_m / 12.0 * (3 * wh_r * wh_r + wh_h*wh_h)}" iyz="0.0"
	  izz="${wh_m / 2.0 * (wh_r * wh_r)}"/>
		</inertial>

	</link>

	<link name="wheel_r2">
		<collision>
			<origin xyz="${wh_h/2 + 0.01} 0 0" rpy="0 1.57075 0"/>
			<geometry>
				<cylinder length="${wh_h}" radius="${wh_r}"/>
			</geometry>
		</collision>

		<visual>
			<origin xyz="${wh_h/2 + 0.01} 0 0" rpy="0 1.57075 0"/>
			<geometry>
				<cylinder length="${wh_h}" radius="${wh_r}"/>
			</geometry>
		</visual>

		<inertial>
			<origin xyz="${wh_h/2 + 0.01} 0 0" rpy="0 1.57075 0"/>
			<mass value="${wh_m}"/>
			<inertia
	  ixx="${wh_m / 12.0 * (3 * wh_r * wh_r + wh_h*wh_h)}" ixy="0.0" ixz="0.0"
	  iyy="${wh_m / 12.0 * (3 * wh_r * wh_r + wh_h*wh_h)}" iyz="0.0"
	  izz="${wh_m / 2.0 * (wh_r * wh_r)}"/>
		</inertial>

	</link>

	<link name="wheel_l2">
		<collision>
			<origin xyz="${-wh_h/2 - 0.01} 0 0" rpy="0 1.57075 0"/>
			<geometry>
				<cylinder length="${wh_h}" radius="${wh_r}"/>
			</geometry>
		</collision>

		<visual>
			<origin xyz="${-wh_h/2 - 0.01} 0 0" rpy="0 1.57075 0"/>
			<geometry>
				<cylinder length="${wh_h}" radius="${wh_r}"/>
			</geometry>
		</visual>

		<inertial>
			<origin xyz="${-wh_h/2 - 0.01} 0 0" rpy="0 1.57075 0"/>
			<mass value="${wh_m}"/>
			<inertia
	  ixx="${wh_m / 12.0 * (3 * wh_r * wh_r + wh_h*wh_h)}" ixy="0.0" ixz="0.0"
	  iyy="${wh_m / 12.0 * (3 * wh_r * wh_r + wh_h*wh_h)}" iyz="0.0"
	  izz="${wh_m / 2.0 * (wh_r * wh_r)}"/>
		</inertial>

	</link>

</robot>

